Workbook
Name Actual: (Academic!PeriodInActual*(Academic!#REF!>0))*Academic!PeriodInPlan
Name Actual: ('Academic (2)'!PeriodInActual*('Academic (2)'!#REF!>0))*'Academic (2)'!PeriodInPlan
Name Actual: ('EMR '!PeriodInActual*('EMR '!#REF!>0))*'EMR '!PeriodInPlan
Name Actual: ('EMR - Activity wise'!PeriodInActual*('EMR - Activity wise'!#REF!>0))*'EMR - Activity wise'!PeriodInPlan
Name Actual: ('EMR Backup Sheet'!PeriodInActual*('EMR Backup Sheet'!#REF!>0))*'EMR Backup Sheet'!PeriodInPlan
Name Actual: ('OPD '!PeriodInActual*('OPD '!#REF!>0))*'OPD '!PeriodInPlan
Name Actual: ('OPD Backup Sheet'!PeriodInActual*('OPD Backup Sheet'!#REF!>0))*'OPD Backup Sheet'!PeriodInPlan
Name Actual: ('OPD - Summary'!PeriodInActual*('OPD - Summary'!#REF!>0))*'OPD - Summary'!PeriodInPlan
Name Actual: ('Type 3'!PeriodInActual*('Type 3'!#REF!>0))*'Type 3'!PeriodInPlan
Name Actual: ('Type 4'!PeriodInActual*('Type 4'!#REF!>0))*'Type 4'!PeriodInPlan
Name Actual: ('Type 5'!PeriodInActual*('Type 5'!#REF!>0))*'Type 5'!PeriodInPlan
Name Actual: ('UG Female'!PeriodInActual*('UG Female'!#REF!>0))*'UG Female'!PeriodInPlan
Name Actual: ('UG Male'!PeriodInActual*('UG Male'!#REF!>0))*'UG Male'!PeriodInPlan
Name Actual: (PeriodInActual*(#REF!>0))*PeriodInPlan
Name ActualBeyond: Academic!PeriodInActual*(Academic!#REF!>0)
Name ActualBeyond: 'Academic (2)'!PeriodInActual*('Academic (2)'!#REF!>0)
Name ActualBeyond: 'EMR '!PeriodInActual*('EMR '!#REF!>0)
Name ActualBeyond: 'EMR - Activity wise'!PeriodInActual*('EMR - Activity wise'!#REF!>0)
Name ActualBeyond: 'EMR Backup Sheet'!PeriodInActual*('EMR Backup Sheet'!#REF!>0)
Name ActualBeyond: 'OPD '!PeriodInActual*('OPD '!#REF!>0)
Name ActualBeyond: 'OPD Backup Sheet'!PeriodInActual*('OPD Backup Sheet'!#REF!>0)
Name ActualBeyond: 'OPD - Summary'!PeriodInActual*('OPD - Summary'!#REF!>0)
Name ActualBeyond: 'Type 3'!PeriodInActual*('Type 3'!#REF!>0)
Name ActualBeyond: 'Type 4'!PeriodInActual*('Type 4'!#REF!>0)
Name ActualBeyond: 'Type 5'!PeriodInActual*('Type 5'!#REF!>0)
Name ActualBeyond: 'UG Female'!PeriodInActual*('UG Female'!#REF!>0)
Name ActualBeyond: 'UG Male'!PeriodInActual*('UG Male'!#REF!>0)
Name ActualBeyond: PeriodInActual*(#REF!>0)
Name PercentComplete: Academic!PercentCompleteBeyond*Academic!PeriodInPlan
Name PercentComplete: 'Academic (2)'!PercentCompleteBeyond*'Academic (2)'!PeriodInPlan
Name PercentComplete: 'EMR '!PercentCompleteBeyond*'EMR '!PeriodInPlan
Name PercentComplete: 'EMR - Activity wise'!PercentCompleteBeyond*'EMR - Activity wise'!PeriodInPlan
Name PercentComplete: 'EMR Backup Sheet'!PercentCompleteBeyond*'EMR Backup Sheet'!PeriodInPlan
Name PercentComplete: 'OPD '!PercentCompleteBeyond*'OPD '!PeriodInPlan
Name PercentComplete: 'OPD Backup Sheet'!PercentCompleteBeyond*'OPD Backup Sheet'!PeriodInPlan
Name PercentComplete: 'OPD - Summary'!PercentCompleteBeyond*'OPD - Summary'!PeriodInPlan
Name PercentComplete: 'Type 3'!PercentCompleteBeyond*'Type 3'!PeriodInPlan
Name PercentComplete: 'Type 4'!PercentCompleteBeyond*'Type 4'!PeriodInPlan
Name PercentComplete: 'Type 5'!PercentCompleteBeyond*'Type 5'!PeriodInPlan
Name PercentComplete: 'UG Female'!PercentCompleteBeyond*'UG Female'!PeriodInPlan
Name PercentComplete: 'UG Male'!PercentCompleteBeyond*'UG Male'!PeriodInPlan
Name PercentComplete: PercentCompleteBeyond*PeriodInPlan
Name PercentCompleteBeyond: ('EMR '!A$4=MEDIAN('EMR '!A$4,'EMR '!#REF!,'EMR '!#REF!+'EMR '!#REF!)*('EMR '!#REF!>0))*(('EMR '!A$4<(INT('EMR '!#REF!+'EMR '!#REF!*'EMR '!$E1)))+('EMR '!A$4='EMR '!#REF!))*('EMR '!$E1>0)
Name PercentCompleteBeyond: (#REF!=MEDIAN(#REF!,#REF!,#REF!+#REF!)*(#REF!>0))*((#REF!<(INT(#REF!+#REF!*#REF!)))+(#REF!=#REF!))*(#REF!>0)
Name period_selected: Academic!$G$2
Name period_selected: 'Academic (2)'!$F$2
Name period_selected: 'EMR '!$G$2
Name period_selected: 'EMR - Activity wise'!#REF!
Name period_selected: 'EMR Backup Sheet'!#REF!
Name period_selected: 'OPD '!$G$2
Name period_selected: 'OPD Backup Sheet'!#REF!
Name period_selected: 'OPD - Summary'!#REF!
Name period_selected: 'Type 3'!$G$2
Name period_selected: 'Type 4'!#REF!
Name period_selected: 'Type 5'!$G$2
Name period_selected: 'UG Female'!$G$2
Name period_selected: 'UG Male'!$G$2
Name period_selected: #REF!
Name PeriodInActual: Academic!A$4=MEDIAN(Academic!A$4,Academic!#REF!,Academic!#REF!+Academic!#REF!-1)
Name PeriodInActual: 'Academic (2)'!A$4=MEDIAN('Academic (2)'!A$4,'Academic (2)'!#REF!,'Academic (2)'!#REF!+'Academic (2)'!#REF!-1)

Sheet OPD - Summary
A1: OPD BUILDING - 483 Workmen
A2: ACTIVITY | B2: PLAN / ACTUAL START | C2: TARGET DATE | D2: PERCENT COMPLETE ON 24.9.26 | E2: PERCENT COMPLETE ON 29.9.26 | F2: REMARKS
G3: 46174 | H3: =EDATE(G3,1) -> 46204 | I3: =EDATE(H3,1) -> 46235 | J3: =EDATE(I3,1) -> 46266 | K3: =EDATE(J3,1) -> 46296 | L3: =EDATE(K3,1) -> 46327 | M3: =EDATE(L3,1) -> 46357
A4: Structure | D4: 1 | E4: =D4 -> 1 | F4: Completed
A5: Finishes
A6: Brickwork | B6: 45910 | C6: 46305 | D6: 0.95 | E6: 0.97
A7: Internal Plaster | B7: 45991 | C7: 46320 | D7: 0.95 | E7: 0.96
A8: Joineries | B8: 46047 | C8: 46341 | D8: 0.55 | E8: 0.59 | F8: 70% material is available at site.
A9: Fire door frame & shutter | B9: 46102 | C9: =VLOOKUP(A9,[2]OPD!$B$1:$D$111,3,FALSE) -> 46325 | D9: 0.45
A10: Flooring & Dado | B10: 46009 | C10: 46351 | D10: 0.75 | E10: 0.78 | F10: Material Available
A11: False Ceiling | B11: =MIN(B12:B15) -> 46211 | C11: 46366 | D11: =AVERAGE(D12:D15) -> 0.05 | E11: 0.08 | F11: 60% material is available at site.
A12: a) Ground Floor | B12: 46211 | C12: =VLOOKUP(A12,[2]OPD!$B$1:$D$111,3,FALSE) -> 46310 | D12: 0.2
A13: b) First Floor | B13: =B12+25 -> 46236 | C13: =VLOOKUP(A13,[2]OPD!$B$1:$D$111,3,FALSE) -> 46323 | D13: 0
A14: c) Second Floor | B14: =B13+25 -> 46261 | C14: =VLOOKUP(A14,[2]OPD!$B$1:$D$111,3,FALSE) -> 46346 | D14: 0
A15: d) Third Floor | B15: =B14+25 -> 46286 | C15: =VLOOKUP(A15,[2]OPD!$B$1:$D$111,3,FALSE) -> 46371 | D15: 0
A16: Lift facia granite | B16: 46295 | C16: =VLOOKUP(A16,[2]OPD!$B$1:$D$111,3,FALSE) -> 46351 | D16: 0 | E16: 0.04 | F16: Material Available
A17: Interior Works | B17: 46320 | C17: 46380 | D17: 0 | F17: Material delivery from 20th Oct.
A18: SS Handrail | B18: 46341 | C18: 46380 | D18: 0 | F18: Material Delivery from 5th Nov
A19: External
A20: Elevation A | B20: 46116 | C20: 46341 | D20: 0.5 | E20: 0.54 | F20: Façade & Stone available at site
A21: Elevation B | B21: 46191 | C21: 46351 | D21: 0.48 | E21: 0.53 | F21: Façade & Stone available at site
A22: Elevation C | B22: 46244 | C22: 46361 | D22: 0.3 | E22: 0.33 | F22: Material Delivery by 15th Oct
A23: Elevation D | B23: 46259 | C23: 46371 | D23: 0.2 | E23: 0.25 | F23: Material Delivery by 25th Oct
A24: Elevation A | B24: =#REF!+5 -> #REF! | C24: 46315 | D24: 0
A25: Elevation B | B25: =#REF!+5 -> #REF! | C25: 46331 | D25: 0
A26: Elevation C | B26: =#REF!+5 -> #REF! | C26: 46348 | D26: 0
A27: Elevation D | B27: =#REF!+5 -> #REF! | C27: 46361 | D27: 0
A28: Mechanical Electrical Plumbing ( MEP)
A29: First Fixtures
A30: Cable Tray Installation | B30: 46093 | C30: 46315 | D30: 0.8 | E30: 0.83
A31: CI/Gi Piping | B31: 46050 | C31: 46326 | D31: 0.85 | E31: 0.88
A32: Ducting & Insulation | B32: 46002 | C32: 46322 | D32: 0.87 | E32: 0.89
A33: Fire Piping installation | B33: 46032 | C33: 46320 | D33: 0.86 | E33: 0.91
A34: MGPS Copper Piping | B34: 46275 | C34: 46351 | D34: 0.21 | E34: 0.23 | F34: Material Available
A35: PTTS Pipe installation | B35: 46275 | C35: 46341 | D35: 0.16 | E35: 0.18 | F35: Material Available
A36: Under deck Insulation | B36: 46295 | C36: 46323 | D36: 0 | F36: Material Available
A37: Second Fix
A38: Wiring | B38: 46252 | C38: 46346 | D38: 0.38 | E38: 0.45
A39: Cable Laying & Panel Instt. | B39: 46213 | C39: 46354 | D39: 0.45 | E39: 0.51
A40: UPS Installation | B40: 46300 | C40: 46326 | D40: 0 | F40: Material delivery by 5th Oct
...

Sheet OPD
B1: OPD (G+3) | C1: Target Date
B3: Brickwork (Shaft Only) | C3: 46305 | E3: FLOOR | F3: TARGET DATE
B4: Plastering | C4: 46321 | E4: GF | F4: 46310
B5: Doors & Windows | C5: 46341 | E5: FF | F5: 46346
B6: Flooring & Cladding | C6: 46351 | E6: SF | F6: 46366
B7: False Ceiling | C7: 46366 | E7: TF | F7: 46381
B8: Toilets | C8: 46374
B9: Lift works | C9: 46356
B10: External Finishes | C10: 46371
B11: Interior works & SS Handrail | C11: 46380
B12: Power ON | C12: 46361
B13: HVAC Works | C13: 46371

Sheet OPD  Backup Sheet
A1: OPD BUILDING
A2: ACTIVITY | B2: PLAN / ACTUAL START | C2: TARGET DATE | D2: UOM | E2: Scope | F2: Achieved till on 9th Oct | G2: % Achieved | H2: Balance | I2: Asking Rate | J2: No. of workmen Needed | K2: No. of workmen available | L2: Remarks
A4: Finishes
A5: Brickwork | B5: 45910 | C5: 46305 | D5: cum | E5: 4151 | F5: 4115.45 | G5: =F5/E5 -> 0.9914358 | H5: =(E5-F5)*G5 -> 35.245543 | I5: =H5/(C5-(IF(B5>TODAY(),B5,TODAY()))) -> 35.245543 | J5: =ROUND(I5/1,0) -> 35 | K5: 65
A6: Internal Plaster | B6: 45991 | C6: 46320 | D6: sqm | E6: 50950 | F6: 50087.5 | G6: =F6/E6 -> 0.98307164 | H6: =(E6-F6)*G6 -> 847.89929 | I6: =H6/(C6-(IF(B6>TODAY(),B6,TODAY()))) -> 52.993706 | J6: =ROUND(I6/10,0) -> 5 | K6: 7
A7: Joineries | B7: 46047 | C7: 46341 | D7: No. | E7: =206+511 -> 717 | F7: 378 | G7: =F7/E7 -> 0.52719665 | H7: =(E7-F7)*G7 -> 178.71967 | I7: =H7/(C7-(IF(B7>TODAY(),B7,TODAY()))) -> 4.8302612 | J7: =ROUND(I7/3,0) -> 2 | K7: 14
A8: Flooring & Dado | B8: 46009 | C8: 46351 | D8: sqm | E8: 29200 | F8: 22255 | G8: =F8/E8 -> 0.76215753 | H8: =(E8-F8)*G8 -> 5293.1841 | I8: =H8/(C8-(IF(B8>TODAY(),B8,TODAY()))) -> 112.62094 | J8: =ROUND(I8/3,0) -> 38 | K8: 30
A9: False ceiling - GF | B9: 46211 | C9: 46310 | D9: sqm | E9: 4152 | F9: 2283.6 | G9: =F9/E9 -> 0.55 | H9: =(E9-F9)*G9 -> 1027.62 | I9: =H9/(C9-(IF(B9>TODAY(),B9,TODAY()))) -> 171.27 | J9: =ROUND(I9/12,0) -> 14 | K9: 9
A10: False ceiling - FF | B10: 46270 | C10: 46323 | D10: sqm | E10: 3598 | F10: 408 | G10: =F10/E10 -> 0.11339633 | H10: =(E10-F10)*G10 -> 361.7343 | I10: =H10/(C10-(IF(B10>TODAY(),B10,TODAY()))) -> 19.038647 | J10: =ROUND(I10/12,0) -> 2 | K10: 5
A11: False ceiling - SF | B11: 46331 | C11: 46346 | D11: sqm | E11: 3598 | F11: 0 | G11: =F11/E11 -> 0 | H11: =(E11-F11)*G11 -> 0 | I11: =H11/(C11-(IF(B11>TODAY(),B11,TODAY()))) -> 0 | J11: =ROUND(I11/12,0) -> 0
A12: False ceiling - TF | B12: 46356 | C12: 46371 | D12: sqm | E12: 3715 | F12: 0 | G12: =F12/E12 -> 0 | H12: =(E12-F12)*G12 -> 0 | I12: =H12/(C12-(IF(B12>TODAY(),B12,TODAY()))) -> 0 | J12: =ROUND(I12/12,0) -> 0
A13: Lift facia granite | B13: 46295 | C13: 46351 | D13: sqm | E13: =60*4 -> 240 | F13: 0 | G13: =F13/E13 -> 0 | H13: =(E13-F13)*G13 -> 0 | I13: =H13/(C13-(IF(B13>TODAY(),B13,TODAY()))) -> 0 | J13: =ROUND(I13/6,0) -> 0 | L13: Will start from 12th Oct
A14: Interior Works | B14: 46320 | C14: 46380 | D14: sqm | E14: 640 | F14: 0 | G14: =F14/E14 -> 0 | H14: =(E14-F14)*G14 -> 0 | I14: =H14/(C14-(IF(B14>TODAY(),B14,TODAY()))) -> 0 | J14: =ROUND(I14/8,0) -> 0 | L14: Drawings & TDS under review
A15: SS Handrail | B15: 46341 | C15: 46380 | D15: Rm | E15: =96*4+45+21+25 -> 475 | F15: 0 | G15: =F15/E15 -> 0 | H15: =(E15-F15)*G15 -> 0 | I15: =H15/(C15-(IF(B15>TODAY(),B15,TODAY()))) -> 0 | J15: =ROUND(I15/9,0) -> 0 | L15: Drawings will be submitted by 10th Oct
A16: External
A17: Elevation A
A18: Brickwork | B18: 46308 | C18: 46315 | D18: sqm | E18: 865 | F18: 825 | G18: =F18/E18 -> 0.95375723 | H18: =(E18-F18)*G18 -> 38.150289 | I18: =H18/(C18-(IF(B18>TODAY(),B18,TODAY()))) -> 5.4500413 | J18: =ROUND(I18/1,0) -> 5 | L18: MS Canopy foundation WIP
A19: Plaster | B19: =C18+1 -> 46316 | C19: =C18+8 -> 46323 | D19: sqm | E19: 1012 | F19: 896 | G19: =F19/E19 -> 0.88537549 | H19: =(E19-F19)*G19 -> 102.70356 | I19: =H19/(C19-(IF(B19>TODAY(),B19,TODAY()))) -> 14.671937 | J19: =ROUND(I19/10,0) -> 1
A20: MS framing | B20: 46296 | C20: 46333 | D20: sqm | E20: 345 | F20: 27 | G20: =F20/E20 -> 0.07826087 | H20: =(E20-F20)*G20 -> 24.886957 | I20: =H20/(C20-(IF(B20>TODAY(),B20,TODAY()))) -> 0.85817091 | J20: =ROUND(I20/12,0) -> 0 | K20: 4 | L20: Mockup works in progress
A21: Stone Cladding | B21: =B20+3 -> 46299 | C21: =C20+3 -> 46336 | D21: sqm | E21: 345 | F21: 0 | G21: =F21/E21 -> 0 | H21: =(E21-F21)*G21 -> 0 | I21: =H21/(C21-(IF(B21>TODAY(),B21,TODAY()))) -> 0 | J21: =ROUND(I21/10,0) -> 0
A22: Glazing | B22: 46305 | C22: =C21+5 -> 46341 | D22: sqm | E22: =28*0.96*20.7+13.46*8.4 -> 669.48 | F22: 0 | G22: =F22/E22 -> 0 | H22: =(E22-F22)*G22 -> 0 | I22: =H22/(C22-(IF(B22>TODAY(),B22,TODAY()))) -> 0 | J22: =ROUND(I22/5,0) -> 0 | L22: Mockup works in progress
A23: Paint | B23: =C22+1 -> 46342 | C23: =B23+4 -> 46346 | D23: sqm | E23: 1270 | F23: 0 | G23: =F23/E23 -> 0 | H23: =(E23-F23)*G23 -> 0 | I23: =H23/(C23-(IF(B23>TODAY(),B23,TODAY()))) -> 0 | J23: =ROUND(I23/10,0) -> 0
A24: Elevation B
A25: Brickwork | B25: 46297 | C25: 46318 | D25: sqm | E25: =51/0.115 -> 443.47826 | F25: 408 | G25: =F25/E25 -> 0.92 | H25: =(E25-F25)*G25 -> 32.64 | I25: =H25/(C25-(IF(B25>TODAY(),B25,TODAY()))) -> 2.3314286 | J25: =ROUND(I25/1,0) -> 2 | K25: 4
A26: Plaster | B26: =B25+1 -> 46298 | C26: =C25+8 -> 46326 | D26: sqm | E26: 780 | F26: 590 | G26: =F26/E26 -> 0.75641026 | H26: =(E26-F26)*G26 -> 143.71795 | I26: =H26/(C26-(IF(B26>TODAY(),B26,TODAY()))) -> 6.532634 | J26: =ROUND(I26/10,0) -> 1
A27: MS framing | B27: 46300 | C27: 46337 | D27: sqm | E27: 215 | F27: 78 | G27: =F27/E27 -> 0.3627907 | H27: =(E27-F27)*G27 -> 49.702326 | I27: =H27/(C27-(IF(B27>TODAY(),B27,TODAY()))) -> 1.5061311 | J27: =ROUND(I27/12,0) -> 0 | K27: 11
A28: Stone Cladding | B28: =B27+3 -> 46303 | C28: =C27+3 -> 46340 | D28: sqm | E28: 215 | F28: 14 | G28: =F28/E28 -> 0.065116279 | H28: =(E28-F28)*G28 -> 13.088372 | I28: =H28/(C28-(IF(B28>TODAY(),B28,TODAY()))) -> 0.36356589 | J28: =ROUND(I28/10,0) -> 0 | K28: 4
A29: Glazing | B29: 46311 | C29: =C28+7 -> 46347 | D29: sqm | E29: =16*2.05*8.4 -> 275.52 | F29: 0 | G29: =F29/E29 -> 0 | H29: =(E29-F29)*G29 -> 0 | I29: =H29/(C29-(IF(B29>TODAY(),B29,TODAY()))) -> 0 | J29: =ROUND(I29/5,0) -> 0
A30: Paint | B30: =C29+1 -> 46348 | C30: =B30+3 -> 46351 | D30: sqm | E30: 435 | F30: 0 | G30: =F30/E30 -> 0 | H30: =(E30-F30)*G30 -> 0 | I30: =H30/(C30-(IF(B30>TODAY(),B30,TODAY()))) -> 0 | J30: =ROUND(I30/10,0) -> 0
A31: Elevation C
A32: Brickwork | B32: 46299 | C32: 46325 | D32: sqm | E32: 521 | F32: 497 | G32: =F32/E32 -> 0.95393474 | H32: =(E32-F32)*G32 -> 22.894434 | I32: =H32/(C32-(IF(B32>TODAY(),B32,TODAY()))) -> 1.0902111 | J32: =ROUND(I32/1,0) -> 1 | K32: 4
A33: Plaster | B33: =B32+4 -> 46303 | C33: =C32+8 -> 46333 | D33: sqm | E33: 825 | F33: 396 | G33: =F33/E33 -> 0.48 | H33: =(E33-F33)*G33 -> 205.92 | I33: =H33/(C33-(IF(B33>TODAY(),B33,TODAY()))) -> 7.1006897 | J33: =ROUND(I33/10,0) -> 1 | K33: 5
A34: MS framing | B34: 46320 | C34: 46348 | D34: sqm | E34: 285 | F34: 0 | G34: =F34/E34 -> 0 | H34: =(E34-F34)*G34 -> 0 | I34: =H34/(C34-(IF(B34>TODAY(),B34,TODAY()))) -> 0 | J34: =ROUND(I34/12,0) -> 0
A35: Stone Cladding | B35: =B34+3 -> 46323 | C35: =C34+3 -> 46351 | D35: sqm | E35: =E34 -> 285 | F35: 0 | G35: =F35/E35 -> 0 | H35: =(E35-F35)*G35 -> 0 | I35: =H35/(C35-(IF(B35>TODAY(),B35,TODAY()))) -> 0 | J35: =ROUND(I35/10,0) -> 0
A36: Glazing | B36: 46311 | C36: =C35+6 -> 46357 | D36: sqm | E36: 312 | F36: 0 | G36: =F36/E36 -> 0 | H36: =(E36-F36)*G36 -> 0 | I36: =H36/(C36-(IF(B36>TODAY(),B36,TODAY()))) -> 0 | J36: =ROUND(I36/5,0) -> 0
A37: Paint | B37: =C36+1 -> 46358 | C37: =B37+3 -> 46361 | D37: sqm | E37: 456 | F37: 0 | G37: =F37/E37 -> 0 | H37: =(E37-F37)*G37 -> 0 | I37: =H37/(C37-(IF(B37>TODAY(),B37,TODAY()))) -> 0 | J37: =ROUND(I37/10,0) -> 0
A38: Elevation D
A39: Brickwork | B39: 46310 | C39: 46331 | D39: sqm | E39: =51/0.115 -> 443.47826 | F39: 425.73913 | G39: =F39/E39 -> 0.96 | H39: =(E39-F39)*G39 -> 17.029565 | I39: =H39/(C39-(IF(B39>TODAY(),B39,TODAY()))) -> 0.81093168 | J39: =ROUND(I39/1,0) -> 1 | L39: Backfilling Works in progress
A40: Plaster | B40: =C39+1 -> 46332 | C40: =C39+10 -> 46341 | D40: sqm | E40: 780 | F40: 0 | G40: =F40/E40 -> 0 | H40: =(E40-F40)*G40 -> 0 | I40: =H40/(C40-(IF(B40>TODAY(),B40,TODAY()))) -> 0 | J40: =ROUND(I40/10,0) -> 0
A41: MS framing | B41: 46331 | C41: 46348 | D41: sqm | E41: 215 | F41: 0 | G41: =F41/E41 -> 0 | H41: =(E41-F41)*G41 -> 0 | I41: =H41/(C41-(IF(B41>TODAY(),B41,TODAY()))) -> 0 | J41: =ROUND(I41/12,0) -> 0
...

Sheet EMR
B1: EMR (G+3) | C1: Target Date
B3: Brickwork | C3: 46320
B4: Plastering | C4: 46346 | E4: FLOOR | F4: TARGET DATE
B5: Doors & Windows | C5: 46346 | E5: GF | F5: 46323
B6: Flooring & Cladding | C6: 46356 | E6: FF | F6: 46351
B7: False Ceiling | C7: 46374 | E7: SF | F7: 46374
B8: Toilets | C8: 46384 | E8: TF | F8: 46381
B9: Lift Works | C9: 46382
B10: External Finishes | C10: 46367
B11: Interior works & SS Handrail | C11: 46380
B12: CSSD | C12: 46341
B13: Power ON | C13: 46368
B14: HVAC Works | C14: 46377
B15: OT Works / ICU | C15: 46380

Sheet EMR Backup Sheet
A1: EMERGENCY BUILDING
A3: ACTIVITY | B3: PLAN / ACTUAL START | C3: Target Date | D3: UOM | E3: SCOPE | F3: Achieved till 9th Oct | G3: % Achieved | H3: Balance | I3: Asking Rate | J3: Manpower Needed | K3: Manpower Available
A5: Finishes
A6: Brickwork | B6: 45938 | C6: 46320 | D6: Cum | E6: =4931-703 -> 4228 | F6: 4101.16 | G6: =F6/E6 -> 0.97 | H6: =E6-F6 -> 126.84 | I6: =H6/(C6-(IF(B6>TODAY(),B6,TODAY()))) -> 7.9275 | J6: =ROUND(I6/1,0) -> 8 | K6: 8
A7: Internal Plaster | B7: 46032 | C7: 46336 | D7: sqm | E7: 55280 | F7: 44989 | G7: =F7/E7 -> 0.81383864 | H7: =E7-F7 -> 10291 | I7: =H7/(C7-(IF(B7>TODAY(),B7,TODAY()))) -> 321.59375 | J7: =ROUND(I7/12,0) -> 27 | K7: 30
A8: Joineries | B8: 46102 | C8: 46371 | D8: No. | E8: 782 | F8: 445.74 | G8: =F8/E8 -> 0.57 | H8: =E8-F8 -> 336.26 | I8: =H8/(C8-(IF(B8>TODAY(),B8,TODAY()))) -> 5.018806 | J8: =ROUND(I8/3,0) -> 2 | K8: 0
A9: Flooring & Dado | B9: 46073 | C9: =VLOOKUP(A9,[1]EMR!$B$7:$D$131,3,FALSE) -> 46356 | D9: sqm | E9: =17000+7221+1921 -> 26142 | F9: 21499.02 | G9: =F9/E9 -> 0.82239385 | H9: =E9-F9 -> 4642.98 | I9: =H9/(C9-(IF(B9>TODAY(),B9,TODAY()))) -> 89.288077 | J9: =ROUND(I9/10,0) -> 9 | K9: 12
A10: False ceiling - GF | B10: 46310 | C10: 46346 | D10: sqm | E10: =4152*1.5 -> 6228 | F10: 186.84 | G10: =F10/E10 -> 0.03 | H10: =E10-F10 -> 6041.16 | I10: =H10/(C10-(IF(B10>TODAY(),B10,TODAY()))) -> 167.81 | J10: =ROUND(I10/12,0) -> 14
A11: False ceiling - FF | B11: =B10+10 -> 46320 | C11: 46336 | D11: sqm | E11: =3598*1.5 -> 5397 | F11: 0 | G11: =F11/E11 -> 0 | H11: =E11-F11 -> 5397 | I11: =H11/(C11-(IF(B11>TODAY(),B11,TODAY()))) -> 337.3125 | J11: =ROUND(I11/12,0) -> 28
A12: False ceiling - SF | B12: =B11+10 -> 46330 | C12: 46351 | D12: sqm | E12: =3598*1.5 -> 5397 | F12: 0 | G12: =F12/E12 -> 0 | H12: =E12-F12 -> 5397 | I12: =H12/(C12-(IF(B12>TODAY(),B12,TODAY()))) -> 257 | J12: =ROUND(I12/12,0) -> 21
A13: False ceiling - TF | B13: =B12+10 -> 46340 | C13: 46366 | D13: sqm | E13: =3715*1.5 -> 5572.5 | F13: 0 | G13: =F13/E13 -> 0 | H13: =E13-F13 -> 5572.5 | I13: =H13/(C13-(IF(B13>TODAY(),B13,TODAY()))) -> 214.32692 | J13: =ROUND(I13/12,0) -> 18
A14: Lift lobby | B14: 46315 | C14: 46376 | D14: sqm | E14: 290 | F14: 0 | G14: =F14/E14 -> 0 | H14: =E14-F14 -> 290 | I14: =H14/(C14-(IF(B14>TODAY(),B14,TODAY()))) -> 4.7540984 | J14: =ROUND(I14/5,0) -> 1 | K14: 0
A15: Interior Works | B15: 46344 | C15: 46374 | D15: sqm | E15: 530 | F15: 0 | G15: =F15/E15 -> 0 | H15: =E15-F15 -> 530 | I15: =H15/(C15-(IF(B15>TODAY(),B15,TODAY()))) -> 17.666667 | J15: =ROUND(I15/10,0) -> 2 | K15: 0
A16: SS Handrail | B16: 46336 | C16: 46376 | D16: Rm | E16: 475 | F16: 0 | G16: =F16/E16 -> 0 | H16: =E16-F16 -> 475 | I16: =H16/(C16-(IF(B16>TODAY(),B16,TODAY()))) -> 11.875 | J16: =ROUND(I16/10,0) -> 1 | K16: 0
A17: OT Rooms
A18: Ground Floor ( 2 Nos.)
A19: Civil Work | B19: 46167 | C19: 46262 | G19: 1 | H19: 1
A20: OT Works | B20: 46262 | C20: 46310 | G20: 0.54 | H20: =100%-G20 -> 0.46 | J20: 4 | K20: 0
A21: 2nd Floor (2 Nos.)
A22: Civil Work | B22: 46193 | C22: 46298 | G22: 1 | H22: =100%-G22 -> 0 | J22: 8 | K22: 8
A23: OT Works | B23: 46298 | C23: 46325 | G23: 0.12 | H23: =100%-G23 -> 0.88
A24: 3rd Floor (12 Nos.)
A25: Civil Work | B25: 46208 | C25: 46325 | G25: 0.45 | H25: =100%-G25 -> 0.55 | J25: 10 | K25: 12
A26: OT Works | B26: 46325 | C26: 46377 | G26: 0 | H26: =100%-G26 -> 1
A27: CSSD Room
A28: Civil Work | B28: 46213 | C28: 46264 | G28: 1 | H28: =100%-G28 -> 0 | I28: - | J28: -
A29: Service Oriented Work | B29: 46266 | C29: 46351 | G29: 0.58 | H29: =100%-G29 -> 0.42
A30: Above Terrace
A31: Staircase - Head Room | B31: 46280 | C31: 46325 | D31: CUM | E31: 340 | F31: 129.2 | G31: =F31/E31 -> 0.38 | H31: =E31-F31 -> 210.8 | I31: =H31/(C31-(IF(B31>TODAY(),B31,TODAY()))) -> 10.038095 | J31: =ROUND(I31/4,0) -> 3 | K31: 3
A32: Over Head Tank | B32: 46290 | C32: 46327 | D32: sqm | E32: 350 | F32: 147 | G32: =F32/E32 -> 0.42 | H32: =E32-F32 -> 203 | I32: =H32/(C32-(IF(B32>TODAY(),B32,TODAY()))) -> 8.826087 | J32: =ROUND(I32/3,0) -> 3 | K32: 4
A33: Terrace Waterproofing | B33: 46272 | C33: 46325 | D33: sqm | E33: 3754 | F33: 2552.72 | G33: =F33/E33 -> 0.68 | H33: =E33-F33 -> 1201.28 | I33: =H33/(C33-(IF(B33>TODAY(),B33,TODAY()))) -> 57.20381 | J33: =ROUND(I33/10,0) -> 6 | K33: 3
A34: Truss & Polycarbonate Sheet | B34: 46300 | C34: 46320 | D34: sqm | E34: =29*30.5 -> 884.5 | F34: 610.305 | G34: =F34/E34 -> 0.69 | H34: =E34-F34 -> 274.195 | I34: =H34/(C34-(IF(B34>TODAY(),B34,TODAY()))) -> 17.137188 | J34: 2 | K34: 0
A35: External
A36: Elevation A | B36: 46239 | C36: 46366 | D36: sqm | E36: 935 | F36: 392.7 | G36: =F36/E36 -> 0.42 | H36: =E36-F36 -> 542.3 | I36: =H36/(C36-(IF(B36>TODAY(),B36,TODAY()))) -> 8.7467742 | J36: =ROUND(I36/3,0) -> 3 | K36: 8
A37: Elevation B | B37: 46252 | C37: 46368 | D37: sqm | E37: 490 | F37: 68.6 | G37: =F37/E37 -> 0.14 | H37: =E37-F37 -> 421.4 | I37: =H37/(C37-(IF(B37>TODAY(),B37,TODAY()))) -> 6.584375 | J37: =ROUND(I37/3,0) -> 2 | K37: 5
A38: Elevation C | B38: 46270 | C38: 46374 | D38: sqm | E38: 564 | F38: 112.8 | G38: =F38/E38 -> 0.2 | H38: =E38-F38 -> 451.2 | I38: =H38/(C38-(IF(B38>TODAY(),B38,TODAY()))) -> 6.4457143 | J38: =ROUND(I38/3,0) -> 2 | K38: 2
A39: Elevation D | B39: 46244 | C39: 46366 | D39: sqm | E39: 485 | F39: 82.45 | G39: =F39/E39 -> 0.17 | H39: =E39-F39 -> 402.55 | I39: =H39/(C39-(IF(B39>TODAY(),B39,TODAY()))) -> 6.4927419 | J39: =ROUND(I39/3,0) -> 2 | K39: 0
A40: Fascia Beam | B40: 46267 | C40: 46356 | D40: Rm | E40: =(70.6+77.6+70.6)*2 -> 437.6 | F40: 126.904 | G40: =F40/E40 -> 0.29 | H40: =E40-F40 -> 310.696 | I40: =H40/(C40-(IF(B40>TODAY(),B40,TODAY()))) -> 5.9749231 | J40: =ROUND(I40/3,0) -> 2 | K40: 3
A41: Mechanical Electrical Plumbing ( MEP)
A42: First Fixtures
...

Sheet Academic
B1: ACADEMIC BUILDING
E2: Period Highlight: | G2: 46296 | J2: Plan Duration | M2: % Complete
B3: ACTIVITY | C3: PLAN START | D3: Target Date | E3: PERCENT COMPLETE | F3: Remarks | G3: PERIODS
G4: 45901 | H4: =EDATE(G4,1) -> 45931 | I4: =EDATE(H4,1) -> 45962 | J4: =EDATE(I4,1) -> 45992 | K4: =EDATE(J4,1) -> 46023 | L4: =EDATE(K4,1) -> 46054 | M4: =EDATE(L4,1) -> 46082 | N4: =EDATE(M4,1) -> 46113 | O4: =EDATE(N4,1) -> 46143 | ... V4: =EDATE(U4,1) -> 46357
B5: Structure | E5: 1
B6: Finishes
B7: Brickwork | C7: 45843 | D7: 46295 | E7: 0.95
B8: Plaster | C8: 45881 | D8: 46305 | E8: 0.84
B9: Aluminum Joineries | C9: 46091 | D9: 46371 | E9: 0.55
B10: Fire door frame & shutter | C10: 46072 | D10: 46371 | E10: 0.45
B11: Flooring & Dado | C11: 46063 | D11: 46356 | E11: 0.65
B12: False Ceiling | C12: 46193 | D12: 46356 | E12: 0.2
B13: a) Ground Floor
B14: b) First Floor
B15: c) Second Floor
B16: d) Third Floor
B17: SS Handrail
B18: Above Terrace
B19: OHT Waterproofing & Tiling
B20: LMR
B21: Terrace Waterproofing&HRT Tiles
B22: Pedestals
B23: Polycarbonate Sheet
B24: External (Shaft brickwork & Plaster)
... B34: Structural Glazing
B35: Elevation A | C35: =C30+5 -> 5 | D35: 46315 | E35: 0
B36: Elevation B | C36: =C31+5 -> 5 | D36: 46331 | E36: 0
B37: Elevation C | C37: =C32+5 -> 5 | D37: 46348 | E37: 0
B38: Elevation D | C38: =C33+5 -> 5 | D38: 46361 | E38: 0
B39: MEP
B40: Second Fix
B41: Electrical | C41: 46252 | D41: 46366 | E41: 0.39
B42: PHE | C42: 46231 | D42: 46382 | E42: 0.42
B43: HVAC | C43: 46203 | D43: 46374 | E43: 0.58
B44: Firefighting | C44: 46217 | D44: 46376 | E44: 0.41
B45: ELV | C45: 46237 | D45: 46381 | E45: 0.35
B46: Final Fixture
B47: Electrical
B48: PHE
B49: HVAC
...

Sheet EMR - Activity wise
A1: EMERGENCY BUILDING - 396 Workmen
A3: ACTIVITY | B3: PLAN / ACTUAL START | C3: TARGET DATE | D3: % COMPLETE ON 24.09.26 | E3: % COMPLETE ON 29.09.26 | F3: REMARKS | G3: 46174 | H3: =EDATE(G3,1) -> 46204 | I3: =EDATE(H3,1) -> 46235 | J3: =EDATE(I3,1) -> 46266 | K3: =EDATE(J3,1) -> 46296 | L3: =EDATE(K3,1) -> 46327 | M3: =EDATE(L3,1) -> 46357
A5: Structure | D5: 1 | E5: =D5 -> 1
A6: Finishes
A7: Brickwork | B7: 45938 | C7: 46320 | D7: 0.95 | E7: 0.96
A8: Internal Plaster | B8: 46032 | C8: 46336 | D8: 0.75 | E8: 0.78
A9: Joineries | B9: 46102 | C9: 46371 | D9: 0.55 | E9: 0.57
A10: Fire door frame & shutter | B10: 46102 | C10: =VLOOKUP(A10,[4]EMR!$B$7:$D$131,3,FALSE) -> 46371 | D10: 0.45
A11: Flooring & Dado | B11: 46073 | C11: =VLOOKUP(A11,[4]EMR!$B$7:$D$131,3,FALSE) -> 46356 | D11: 0.75 | E11: 0.79
A12: False Ceiling | B12: 46323 | C12: 46378 | D12: 0 | F12: Material delivery by 25th Oct.
A13: Lift lobby | B13: 46315 | C13: 46376 | D13: 0 | F13: Material Available
A14: Interior Works | B14: 46344 | C14: 46384 | D14: 0 | F14: Material delivery from 15th Nov
A15: SS Handrail | B15: 46336 | C15: 46376 | D15: 0 | F15: Material delivery from 5th Nov.
A16: OT Rooms
A17: Ground Floor ( 2 Nos.)
A18: Civil Work | B18: 46167 | C18: 46262 | D18: 1 | E18: =D18 -> 1
A19: OT Works | B19: 46262 | C19: 46344 | D19: 0.35 | E19: 0.38 | F19: Material Available
A20: 2nd Floor (2 Nos.)
A21: Civil Work | B21: 46193 | C21: 46298 | D21: 0.95 | E21: 0.96
A22: OT Works | B22: 46298 | C22: 46361 | D22: 0 | E22: =D22 -> 0 | F22: Material Available
A23: 3rd Floor (12 Nos.)
A24: Civil Work | B24: 46208 | C24: 46325 | D24: 0.25 | E24: 0.27
A25: OT Works | B25: 46325 | C25: 46387 | D25: 0 | E25: =D25 -> 0 | F25: Material Available
A26: CSSD Room
A27: Civil Work | B27: 46213 | C27: 46264 | D27: 1 | E27: =D27 -> 1
A28: Service Oriented Work | B28: 46266 | C28: 46351 | D28: 0.52 | E28: 0.54
A29: Above Terrace
A30: Staircase - Head Room | B30: 46280 | C30: 46325 | D30: 0.25 | E30: 0.33
A31: Over Head Tank | B31: 46290 | C31: 46327 | D31: 0.35 | E31: 0.42
A32: Terrace Waterproofing | B32: 46272 | C32: 46338 | D32: 0.65 | E32: 0.68
A33: Truss & Polycarbonate Sheet | B33: 46270 | C33: 46320 | D33: 0.6 | E33: 0.64 | F33: Truss erected. Sheet fixing works in progress
A34: External
A35: Elevation A | B35: 46239 | C35: 46355 | D35: 0.35 | E35: 0.38
A36: Elevation B | B36: 46252 | C36: 46368 | D36: 0.1 | E36: 0.14
A37: Elevation C | B37: 46270 | C37: 46384 | D37: 0.05 | E37: 0.08
A38: Elevation D | B38: 46244 | C38: 46386 | D38: 0.15 | E38: 0.17
A39: Fascia Beam | B39: 46267 | C39: 46346 | D39: 0.19 | E39: 0.24
A40: Mechanical Electrical Plumbing ( MEP)
A41: First Fixtures
A42: Cable Tray Installation | B42: 46034 | C42: 46275 | D42: 1 | E42: =D42 -> 1
...

Sheet Academic (2)
A1: ACADEMIC BUILDING
I2: Plan Duration | L2: % Complete
A3: ACTIVITY | B3: PLAN / ACTUAL START | C3: TARGET DATE | D3: PERCENT COMPLETE | E3: REMARKS
F4: 46174 | G4: =EDATE(F4,1) -> 46204 | H4: =EDATE(G4,1) -> 46235 | I4: =EDATE(H4,1) -> 46266 | J4: =EDATE(I4,1) -> 46296 | K4: =EDATE(J4,1) -> 46327 | L4: =EDATE(K4,1) -> 46357
A5: Structure | D5: 1
A6: Finishes
A7: Brickwork | B7: 45843 | C7: 46305 | D7: 0.95
A8: Internal Plaster | B8: 45881 | C8: 46315 | D8: 0.84
A9: Joineries | B9: 46091 | C9: 46371 | D9: 0.55
A10: Flooring & Dado | B10: 46063 | C10: 46356 | D10: 0.65
A11: False Ceiling | B11: 46193 | C11: 46374 | D11: 0.2
A12: a) Ground Floor
A13: b) First Floor
A14: c) Second Floor
A15: d) Third Floor
A16: Interior Works | B16: 46344 | C16: 46384 | D16: 0 | E16: Material delivery from 15th Nov
A17: SS Handrail | B17: 46336 | C17: 46376 | D17: 0 | E17: Material delivery from 5th Nov.
A18: External
A19: Elevation A | B19: 46239 | C19: 46355 | D19: 0.45
A20: Elevation B | B20: 46252 | C20: 46368 | D20: 0.12
A21: Elevation C | B21: 46270 | C21: 46384 | D21: 0.28
A22: Elevation D | B22: 46244 | C22: 46386 | D22: 0.41
A23: Mechanical Electrical Plumbing ( MEP)
A24: First Fixtures
A25: CI/GI Piping | B25: 46223 | C25: 46382 | D25: 0.45
A26: Fire Piping installation | B26: 46202 | C26: 46371 | D26: 0.52
A27: Second Fix
A28: Wiring | B28: 46252 | C28: 46366 | D28: 0.22
A29: Cable Laying & Panel Instt. | B29: 46263 | C29: 46336 | D29: 0.55
A30: Dropper Installation | B30: 46275 | C30: 46370 | D30: 0.14
A31: AHU Connection | B31: 46195 | C31: 46341 | D31: 0.82
A32: Wet Riser & FHC installation | B32: 46231 | C32: 46377 | D32: 0.42
A33: CAT 6 cabling | B33: 46203 | C33: 46374 | D33: 0.58
A34: PA & FAS cabling | B34: 46217 | C34: 46376 | D34: 0.41
A35: Network Switch | B35: 46237 | C35: 46378 | D35: 0.35
A36: Lift Installation with slow speed
A37: 2 Nos. | B37: =C37-45 -> 46232 | C37: 46277 | D37: 1
A38: 2 Nos. | B38: 46307 | C38: =B38+50 -> 46357 | D38: 0 | E38: Material available
A39: 2 Nos. | B39: 46313 | C39: =B39+50 -> 46363 | D39: 0 | E39: Material available
A40: Permanent Power
...

Sheet Type 4
A1: TYPE 4 BUILDING
H2: % Complete | K2: Plan Duration
A3: ACTIVITY | B3: PLAN / ACTUAL START | C3: TARGET DATE | D3: PERCENT COMPLETE | E3: REMARKS
F4: 46174 | G4: =EDATE(F4,1) -> 46204 | H4: =EDATE(G4,1) -> 46235 | I4: =EDATE(H4,1) -> 46266 | J4: =EDATE(I4,1) -> 46296 | K4: =EDATE(J4,1) -> 46327 | L4: =EDATE(K4,1) -> 46357
A5: Structure | D5: 1
A6: Finishes
A7: Brickwork | B7: 46143 | C7: 46275 | D7: 1
A8: Internal Plaster | B8: 46170 | C8: 46284 | D8: 1
A9: Joineries | B9: 46190 | C9: 46341 | D9: 0.29
A10: Flooring & Dado | B10: 46242 | C10: 46336 | D10: 0.55
A11: False Ceiling | B11: 46285 | C11: 46315 | D11: 0
A12: Lift Lobby Cladding | B12: 46315 | C12: 46335 | D12: 0
A13: SS Handrail | B13: 46296 | C13: 46346 | D13: 0
A14: Putty + Paint | B14: 46267 | C14: 46346 | D14: 0.25
A15: External
A16: External Plaster | B16: 46185 | C16: 46290 | D16: 0.95
A17: External Shaft | B17: 46212 | C17: 46325 | D17: 0.55
A18: Above Terrace
A19: Over Head Tank | B19: 46262 | C19: 46301 | D19: ='UG MALE backup'!E48/'UG MALE backup'!D48 -> 0
A20: Terrace Waterproofing | B20: 46283 | C20: 46295 | D20: 0.2
A21: Mechanical Electrical Plumbing ( MEP)
A22: Frist Fix
A23: Electrical | B23: 46163 | C23: 46290 | D23: 0.96
A24: PHE | B24: 46149 | C24: 46295 | D24: 0.88
A25: Firefighting | B25: 46215 | C25: 46291 | D25: 0.9
A26: ELV | B26: 46224 | C26: 46295 | D26: 0.67
A27: Second Fix
A28: Electrical | B28: 46296 | C28: 46343 | D28: 0
A29: PHE | B29: 46263 | C29: 46284 | D29: 1
A30: HVAC | B30: 46325 | C30: 46341 | D30: 0
A31: Firefighting | B31: 46296 | C31: 46310 | D31: 0
A32: ELV | B32: 46325 | C32: 46351 | D32: 0
A33: Final Fixture
A34: Electrical | B34: 46277 | C34: 46351 | D34: 0.1
A35: PHE | B35: 46327 | C35: 46356 | D35: 0
A36: HVAC | B36: 46336 | C36: 46356 | D36: 0
A37: Firefighting | B37: 46327 | C37: 46336 | D37: 0
A38: ELV | B38: 46337 | C38: 46346 | D38: 0
A39: Terrace
A40: PHE Piping installation | B40: 46296 | C40: 46315 | D40: 0
...

Sheet Type 5
B1: TYPE 5 BUILDING
E2: Period Highlight: | G2: 46266 | J2: Plan Duration | M2: % Complete
B3: ACTIVITY | C3: PLAN START | D3: Target Date | E3: PERCENT COMPLETE | F3: Remarks | G3: PERIODS
G4: 46113 | H4: =EDATE(G4,1) -> 46143 | I4: =EDATE(H4,1) -> 46174 | J4: =EDATE(I4,1) -> 46204 | K4: =EDATE(J4,1) -> 46235 | L4: =EDATE(K4,1) -> 46266 | M4: =EDATE(L4,1) -> 46296 | N4: =EDATE(M4,1) -> 46327 | O4: =EDATE(N4,1) -> 46357 | ... V4: =EDATE(U4,1) -> 46569
B5: Structure Above terrace | C5: 46130 | D5: 46295 | E5: 0.96 | F5: Parapet & OHT
B6: Finishes
B7: Brickwork | C7: 46191 | D7: 46290 | E7: 0.94
B8: Internal Plaster | C8: 46231 | D8: 46310 | E8: 0.58
B9: External Plaster | C9: 46251 | D9: 46315 | E9: 0.42
B10: Doors | D10: 46345 | E10: 0.32
B11: Windows | D11: 46376 | E11: 0.26
B12: Flooring & Dado | C12: 46296 | D12: 46340 | E12: 0
B13: False Ceiling | C13: 46285 | D13: 46315 | E13: 0
B14: a) Ground Floor | C14: 46211 | D14: =VLOOKUP(B14,[2]OPD!$B$1:$D$111,3,FALSE) -> 46310 | E14: 0.2
B15: b) First Floor | C15: =C14+25 -> 46236 | D15: =VLOOKUP(B15,[2]OPD!$B$1:$D$111,3,FALSE) -> 46323 | E15: 0
B16: c) Second Floor | C16: =C15+25 -> 46261 | D16: =VLOOKUP(B16,[2]OPD!$B$1:$D$111,3,FALSE) -> 46346 | E16: 0
B17: d) Third Floor | C17: =C16+25 -> 46286 | D17: =VLOOKUP(B17,[2]OPD!$B$1:$D$111,3,FALSE) -> 46371 | E17: 0
B18: Lift lobby cladding | C18: 46300 | D18: 46346 | E18: 0
B19: SS Handrail | C19: 46296 | D19: 46376 | E19: 0
B20: Putty + Paint | C20: 46267 | D20: 46386 | E20: 0.25
B21: Above Terrace
B22: OHT Waterproofing & Tiling | C22: 46262 | D22: 46301 | E22: ='UG MALE backup'!E48/'UG MALE backup'!D48 -> 0
B23: External (Shaft brickwork & Plaster) | C23: =MIN(C24:C27) -> 46101 | D23: =MAX(D24:D27) -> 46325 | E23: =AVERAGE(E24:E27) -> 0.5925
B24: Elevation A | C24: 46101 | D24: 46264 | E24: 1
B25: Elevation B | C25: 46183 | D25: 46305 | E25: 0.92
B26: Elevation C | C26: 46167 | D26: =VLOOKUP(B26,[2]OPD!$B$1:$D$111,3,FALSE) -> 46295 | E26: 0.45
B27: Elevation D | C27: 46193 | D27: =VLOOKUP(B27,[2]OPD!$B$1:$D$111,3,FALSE) -> 46325 | E27: 0
B28: Elevation A | C28: 46301 | D28: =VLOOKUP(B28,[2]OPD!$B$1:$D$111,3,FALSE) -> 46310 | E28: 0
B29: Elevation B | C29: 46285 | D29: =VLOOKUP(B29,[2]OPD!$B$1:$D$111,3,FALSE) -> 46305 | E29: 0
B30: Elevation C | C30: 46311 | D30: 46325 | E30: 0
B31: Elevation D | C31: 46327 | D31: 46341 | E31: 0
B32: Elevation A | C32: =C28+5 -> 46306 | D32: 46315 | E32: 0
B33: Elevation B | C33: =C29+5 -> 46290 | D33: 46331 | E33: 0
B34: Elevation C | C34: =C30+5 -> 46316 | D34: 46348 | E34: 0
B35: Elevation D | C35: =C31+5 -> 46332 | D35: 46361 | E35: 0
B36: Terrace waterproofing | C36: 46300 | D36: 46331 | E36: 0
B37: MEP
B38: Frist Fix
B39: Electrical | C39: 46215 | D39: 46336 | E39: 0.44
B40: PHE | C40: 46207 | D40: 46336 | E40: 0.39
...

Sheet Type 3
B1: TYPE 3BUILDING
E2: Period Highlight: | G2: 46266 | J2: Plan Duration | M2: % Complete
B3: ACTIVITY | C3: PLAN START | D3: Target Date | E3: PERCENT COMPLETE | F3: Remarks | G3: PERIODS
G4: 45901 | H4: =EDATE(G4,1) -> 45931 | I4: =EDATE(H4,1) -> 45962 | J4: =EDATE(I4,1) -> 45992 | K4: =EDATE(J4,1) -> 46023 | L4: =EDATE(K4,1) -> 46054 | M4: =EDATE(L4,1) -> 46082 | N4: =EDATE(M4,1) -> 46113 | O4: =EDATE(N4,1) -> 46143 | ... V4: =EDATE(U4,1) -> 46357
B5: Structure | E5: 1
B6: Finishes
B7: Plaster | C7: 46185 | D7: 46295 | E7: =('UG MALE backup'!E5+'UG MALE backup'!E7)/('UG MALE backup'!D5+'UG MALE backup'!D7) -> 0.35488004
B8: Doors | C8: 46280 | D8: 46310 | E8: 0.1
B9: Windows | C9: 46296 | D9: 46325 | E9: 0
B10: Flooring & Dado | C10: 46279 | D10: 46320 | E10: 0.1
B11: False Ceiling | C11: 46285 | D11: 46315 | E11: 0
B12: a) Ground Floor | C12: 46211 | D12: =VLOOKUP(B12,[2]OPD!$B$1:$D$111,3,FALSE) -> 46310 | E12: 0.2
B13: b) First Floor | C13: =C12+25 -> 46236 | D13: =VLOOKUP(B13,[2]OPD!$B$1:$D$111,3,FALSE) -> 46323 | E13: 0
B14: c) Second Floor | C14: =C13+25 -> 46261 | D14: =VLOOKUP(B14,[2]OPD!$B$1:$D$111,3,FALSE) -> 46346 | E14: 0
B15: d) Third Floor | C15: =C14+25 -> 46286 | D15: =VLOOKUP(B15,[2]OPD!$B$1:$D$111,3,FALSE) -> 46371 | E15: 0
B16: SS Handrail | C16: 46320 | D16: 46341 | E16: 0
B17: Putty + Paint | C17: 46267 | D17: 46346 | E17: 0.25
B18: Above Terrace
B19: OHT Waterproofing & Tiling | C19: 46262 | D19: 46301 | E19: ='UG MALE backup'!E48/'UG MALE backup'!D48 -> 0
B20: External (Shaft brickwork & Plaster) | C20: =MIN(C21:C24) -> 46101 | D20: =MAX(D21:D24) -> 46325 | E20: =AVERAGE(E21:E24) -> 0.5925
B21: Elevation A | C21: 46101 | D21: 46264 | E21: 1
B22: Elevation B | C22: 46183 | D22: 46305 | E22: 0.92
B23: Elevation C | C23: 46167 | D23: =VLOOKUP(B23,[2]OPD!$B$1:$D$111,3,FALSE) -> 46295 | E23: 0.45
B24: Elevation D | C24: 46193 | D24: =VLOOKUP(B24,[2]OPD!$B$1:$D$111,3,FALSE) -> 46325 | E24: 0
B25: Elevation A | C25: 46301 | D25: =VLOOKUP(B25,[2]OPD!$B$1:$D$111,3,FALSE) -> 46310 | E25: 0
B26: Elevation B | C26: 46285 | D26: =VLOOKUP(B26,[2]OPD!$B$1:$D$111,3,FALSE) -> 46305 | E26: 0
B27: Elevation C | C27: 46311 | D27: 46325 | E27: 0
B28: Elevation D | C28: 46327 | D28: 46341 | E28: 0
B29: Elevation A | C29: =C25+5 -> 46306 | D29: 46315 | E29: 0
B30: Elevation B | C30: =C26+5 -> 46290 | D30: 46331 | E30: 0
B31: Elevation C | C31: =C27+5 -> 46316 | D31: 46348 | E31: 0
B32: Elevation D | C32: =C28+5 -> 46332 | D32: 46361 | E32: 0
B33: MEP
B34: Frist Fix
B35: Electrical | C35: 46167 | D35: 46244 | E35: 1
B36: PHE | C36: 46154 | D36: 46236 | E36: 1
B37: Firefighting | C37: 46293 | D37: 46320 | E37: 0
B38: ELV | C38: 46187 | D38: 46305 | E38: 0.55
B39: Second Fix
B40: Electrical | C40: 46305 | D40: 46320 | E40: 0
...

Sheet UG Female
B1: UG FEMALE
E2: Period Highlight: | G2: 46266 | J2: Plan Duration | M2: % Complete
B3: ACTIVITY | C3: PLAN START | D3: Target Date | E3: PERCENT COMPLETE | F3: Remarks | G3: PERIODS
G4: 45901 | H4: =EDATE(G4,1) -> 45931 | I4: =EDATE(H4,1) -> 45962 | J4: =EDATE(I4,1) -> 45992 | K4: =EDATE(J4,1) -> 46023 | L4: =EDATE(K4,1) -> 46054 | M4: =EDATE(L4,1) -> 46082 | N4: =EDATE(M4,1) -> 46113 | O4: =EDATE(N4,1) -> 46143 | ... V4: =EDATE(U4,1) -> 46357
B5: Structure | E5: 1
B6: Finishes
B7: Brickwork | C7: 46181 | D7: 46310 | E7: ='UGF backup'!E4/'UGF backup'!D4 -> 0.98662207
B8: Plaster | C8: 46222 | D8: 46315 | E8: =('UG MALE backup'!E5+'UG MALE backup'!E7)/('UG MALE backup'!D5+'UG MALE backup'!D7) -> 0.35488004
B9: Aluminum Joineries | C9: 46277 | D9: 46305 | E9: ='UG MALE backup'!E24/'UG MALE backup'!D24 -> 0
B10: Fire door frame & shutter | C10: 46296 | D10: 46305 | E10: ='UG MALE backup'!E27/'UG MALE backup'!D27 -> 0.46153846
B11: Flooring & Dado | C11: 46242 | D11: 46310 | E11: 0.75
B12: False Ceiling | C12: 46285 | D12: 46315 | E12: 0
B13: a) Ground Floor | C13: 46211 | D13: =VLOOKUP(B13,[2]OPD!$B$1:$D$111,3,FALSE) -> 46310 | E13: 0.2
B14: b) First Floor | C14: =C13+25 -> 46236 | D14: =VLOOKUP(B14,[2]OPD!$B$1:$D$111,3,FALSE) -> 46323 | E14: 0
B15: c) Second Floor | C15: =C14+25 -> 46261 | D15: =VLOOKUP(B15,[2]OPD!$B$1:$D$111,3,FALSE) -> 46346 | E15: 0
B16: d) Third Floor | C16: =C15+25 -> 46286 | D16: =VLOOKUP(B16,[2]OPD!$B$1:$D$111,3,FALSE) -> 46371 | E16: 0
B17: SS Handrail | C17: 46285 | D17: 46320 | E17: 0.05
B18: Above Terrace
B19: OHT Waterproofing & Tiling | C19: 46262 | D19: 46301 | E19: ='UG MALE backup'!E48/'UG MALE backup'!D48 -> 0
B20: External (Shaft brickwork & Plaster) | C20: =MIN(C21:C24) -> 46101 | D20: =MAX(D21:D24) -> 46325 | E20: =AVERAGE(E21:E24) -> 0.5925
B21: Elevation A | C21: 46101 | D21: 46264 | E21: 1
B22: Elevation B | C22: 46183 | D22: 46305 | E22: 0.92
B23: Elevation C | C23: 46167 | D23: =VLOOKUP(B23,[2]OPD!$B$1:$D$111,3,FALSE) -> 46295 | E23: 0.45
B24: Elevation D | C24: 46193 | D24: =VLOOKUP(B24,[2]OPD!$B$1:$D$111,3,FALSE) -> 46325 | E24: 0
B25: Elevation A | C25: 46301 | D25: =VLOOKUP(B25,[2]OPD!$B$1:$D$111,3,FALSE) -> 46310 | E25: 0
B26: Elevation B | C26: 46285 | D26: =VLOOKUP(B26,[2]OPD!$B$1:$D$111,3,FALSE) -> 46305 | E26: 0
B27: Elevation C | C27: 46311 | D27: 46325 | E27: 0
B28: Elevation D | C28: 46327 | D28: 46341 | E28: 0
B29: Elevation A | C29: =C25+5 -> 46306 | D29: 46315 | E29: 0
B30: Elevation B | C30: =C26+5 -> 46290 | D30: 46331 | E30: 0
B31: Elevation C | C31: =C27+5 -> 46316 | D31: 46348 | E31: 0
B32: Elevation D | C32: =C28+5 -> 46332 | D32: 46361 | E32: 0
B33: MEP
B34: Frist Fix
B35: Electrical
B36: Cable Tray Installation
B37: PHE
B38: CI Pipiing
B39: GI Piping
B40: HVAC
...

Sheet UGF backup
A1: UG Female Building Balance work Updated 10-09-2026
A2: SL no | B2: Activities | C2: UOM | D2: Scope | E2: Completed | F2: Balance | G2: Strike Date | H2: MEP Clearance | I2: Start Date | J2: Target completion date | K2: Remarks
A4: 1 | B4: Brick work | C4: CUM | D4: 1196 | E4: 1180 | F4: =D4-E4 -> 16 | I4: in progress | J4: 15-10-26 | K4: dipendency external scaffolding Plumbing work
A5: 3 | B5: Sand Plastering Internal | C5: Sqm | D5: 5234 | E5: 4900 | F5: =D5-E5 -> 334 | I5: in progress | J5: 20-10-26 | K5: The false ceiling material stored in the common room will need to be removed
A6: 4 | B6: Sand Plastering External | C6: Sqm | D6: 6051 | E6: 5800 | F6: =D6-E6 -> 251 | I6: in progress | J6: 30-10-26 | K6: Repair & MFH area
A7: 5 | B7: Gypsum Plaster | C7: Sqm | D7: 11938 | E7: 11638 | F7: =D7-E7 -> 300 | I7: in progress | J7: 30-09-26 | K7: Repair
A8: 6 | B8: Granite sill Jamb DW1 | C8: SQM | D8: 368 | E8: 368 | F8: =D8-E8 -> 0
A9: 6A | B9: Granite sill | C9: Nos | D9: 260 | E9: 230 | F9: =D9-E9 -> 30 | I9: in progress | J9: 15-10-26 | K9: only fire door & shaft
A10: 6B | B10: Granite sill window | C10: Nos | D10: 42 | E10: 32 | F10: =D10-E10 -> 10 | I10: in progress | J10: 46325
A11: 7 | B11: Granite Dado | C11: Sqm | D11: 105 | E11: 0 | F11: =D11-E11 -> 105 | I11: aftter lift fixing | J11: 46336 | K11: after lift completion
A12: 8 | B12: Granite Flooring | C12: Sqm | D12: 125 | E12: 0 | F12: =D12-E12 -> 125 | I12: after lift fixing | J12: 46337 | K12: after lift completion
A13: 8B | B13: Granite counter | C13: Sqm | D13: 35 | E13: 4 | F13: =D13-E13 -> 31 | I13: in progress | J13: 15-09-26 | K13: work in progress
A14: 2 | B14: Sub Frame - Door | C14: Nos | D14: 137 | E14: 137 | F14: =D14-E14 -> 0
A15: 9 | B15: Door Frame Room | C15: Nos | D15: 137 | E15: 137 | F15: =D15-E15 -> 0
A16: 10 | B16: Flooring Tile | C16: Sqm | D16: 4646 | E16: 0 | F16: =D16-E16 -> 4646 | H16: font available | I16: 15-09-26 | J16: 25-10-26 | K16: Agency required
A17: 10A | B17: Tile grouting | C17: Sqm | D17: ;4646 | E17: 0 | F17: =D17-E17 -> #VALUE! | I17: 46327 | J17: 20-11-26 | K17: Agency required
A18: 11 | B18: Skerting Tile | C18: RMT | D18: 2448 | E18: 0 | F18: =D18-E18 -> 2448 | H18: font available | I18: 15-09-26 | J18: 25-10-26 | K18: Agency required
A19: 12 | B19: Dado Toilet & Staircase | C19: Sqm | D19: 1350 | E19: 60 | F19: =D19-E19 -> 1290 | H19: font available | I19: 15-09-25 | J19: 30-10-26 | K19: Team Required & IWC fixing pending all toilet, Juan Dark 450*300 & yana dark 300* 450 tile not available in store
A20: 13 | B20: Kota stone flooring | C20: Sqm | D20: 110 | E20: 0 | F20: =D20-E20 -> 110 | H20: font available | I20: 15-09-26 | J20: 30-09-26 | K20: Kota stone reached
A21: 14 | B21: Internal Painting | C21: Sqm | D21: 17172 | E21: 0 | F21: =D21-E21 -> 17172 | I21: in progress | J21: 15-11-26 | K21: 1st coat putty startrd
A22: 15 | B22: External Painting | C22: Sqm | D22: 5457 | E22: 0 | F22: =D22-E22 -> 5457 | I22: 46296 | J22: 20-11-26 | K22: Team required
A23: 16 | B23: False ceiling | C23: Sqm | D23: 535 | E23: 0 | F23: =D23-E23 -> 535 | H23: MEP Clearence require | I23: 20-09-26 | J23: 20-10-26
A24: 17 | B24: Alu. Flush Door | C24: Nos | D24: 137 | E24: 0 | F24: =D24-E24 -> 137 | I24: 46277 | J24: 46305 | K24: Material available
A25: 18 | B25: WPC Door | C25: Nos | D25: 86 | E25: 0 | F25: =D25-E25 -> 86 | H25: front available | I25: 46277 | J25: 30-09-26 | K25: team required
A26: 19 | B26: Bison Door | C26: Nos | D26: 10 | E26: 0 | F26: =D26-E26 -> 10 | H26: front available | I26: Aproval pending | J26: 46336 | K26: materal and team required
A27: 20 | B27: Fire Door | C27: Nos | D27: 26 | E27: 12 | F27: =D27-E27 -> 14 | H27: Front available | I27: 46296 | J27: 46305 | K27: fire rated tennical issue by client
A28: 21 | B28: Alu. DW1 | C28: Nos | D28: 121 | E28: 0 | F28: =D28-E28 -> 121 | H28: Front available | I28: 15-09-26 | J28: 30-09-26 | K28: material not available
A29: 22 | B29: Alu.Windaw frame | C29: Nos | D29: 42 | E29: 14 | F29: =D29-E29 -> 28 | H29: Front available | I29: 15-09-26 | J29: 30-09-26 | K29: material not available
A30: 17B | B30: Alu. Flush Door DW1 | C30: Nos | D30: 121 | E30: 0 | F30: =D30-E30 -> 121 | H30: front available | I30: 15-09-26 | J30: 30-09-26 | K30: material not available
B31: GRC MS frame | C31: Nos | D31: 104 | E31: 75 | F31: =D31-E31 -> 29 | H31: front available 25 no | I31: 13-09-26 | J31: 16-09-26
A32: 23 | B32: GR01 jali | C32: Nos | D32: 104 | E32: 0 | F32: =D32-E32 -> 104 | H32: front available 99 no | I32: 46277 | J32: 25-09-26 | K32: MEP Clearence require
A33: 24 | B33: Bolcony Handrail | C33: Nos | D33: 121 | E33: 0 | F33: =D33-E33 -> 121 | H33: front available 99 no | I33: 25/09/1900 | J33: 25-10-2026 | K33: Material not received
A34: 25 | B34: Brick work | C34: RMT | D34: =121*4 -> 484 | E34: 0 | F34: 484 | I34: 26/09/1900 | J34: 26-10-2026
A35: 26 | B35: waterproofing | C35: Sqm | D35: =2.6*121 -> 314.6 | E35: 0 | F35: 242 | I35: 46296 | J35: 30-10-2026
A36: 27 | B36: Tiling | C36: Sqm | D36: 310 | E36: 0 | F36: 280 | I36: 46327 | J36: 15-11-2026
A37: 28 | B37: Granite top | C37: Sqm | D37: 97 | E37: 0 | F37: 96 | I37: 46327 | J37: 15-11-2026
A38: Terrace UG Female Building Balance work
A39: SL no | B39: Activities | C39: UOM | D39: Scope | E39: Completed | F39: Balance | G39: Strike Date | H39: MEP Clearance | I39: Start Date | J39: Target completion date | K39: Remarks
A41: 1 | B41: Brick work | C41: CUM | D41: 63 | E41: 63 | F41: =D41-E41 -> 0
A42: 2 | B42: Sand Plastering Internal | C42: Sqm | D42: 180 | E42: 180 | F42: =D42-E42 -> 0 | G42: =F42/31 -> 0
...

Sheet EMR 
B1: EMERGENCY BUILDING
E2: Period Highlight: | G2: 46296 | J2: Plan Duration | M2: % Complete
B3: ACTIVITY | C3: PLAN START | D3: Target Date | E3: PERCENT COMPLETE | F3: Remarks | G3: PERIODS
G4: 45901 | H4: =EDATE(G4,1) -> 45931 | I4: =EDATE(H4,1) -> 45962 | J4: =EDATE(I4,1) -> 45992 | K4: =EDATE(J4,1) -> 46023 | L4: =EDATE(K4,1) -> 46054 | M4: =EDATE(L4,1) -> 46082 | N4: =EDATE(M4,1) -> 46113 | O4: =EDATE(N4,1) -> 46143 | ... V4: =EDATE(U4,1) -> 46357
B5: Structure
B6: ST-03 | C6: 46280 | D6: 46310 | E6: 0.25
B7: ST-04 | C7: 46266 | D7: 46305 | E7: 0.05
B8: Fascia Beam | C8: 46267 | D8: 46356 | E8: 0.19
B9: Finishes
B10: Brickwork | C10: 45938 | D10: 46320 | E10: 0.95
B11: Plaster | C11: 46032 | D11: 46336 | E11: 0.75
B12: Joineries | C12: 46102 | D12: 46371 | E12: 0.55
B13: Fire door frame & shutter | C13: 46102 | D13: =VLOOKUP(B13,[4]EMR!$B$7:$D$131,3,FALSE) -> 46371 | E13: 0.45
B14: Flooring & Dado | D14: =VLOOKUP(B14,[4]EMR!$B$7:$D$131,3,FALSE) -> 46356 | E14: 0.75
B15: False Ceiling | C15: =MIN(C16:C19) -> 46211 | D15: =VLOOKUP(B15,[4]EMR!$B$7:$D$131,3,FALSE) -> 46370 | E15: =AVERAGE(E16:E19) -> 0.05
B16: a) Ground Floor | C16: 46211 | D16: =VLOOKUP(B16,[4]EMR!$B$7:$D$131,3,FALSE) -> #N/A | E16: 0.2
B17: b) First Floor | C17: =C16+25 -> 46236 | D17: =VLOOKUP(B17,[4]EMR!$B$7:$D$131,3,FALSE) -> #N/A | E17: 0
B18: c) Second Floor | C18: =C17+25 -> 46261 | D18: =VLOOKUP(B18,[4]EMR!$B$7:$D$131,3,FALSE) -> #N/A | E18: 0
B19: d) Third Floor | C19: =C18+25 -> 46286 | D19: =VLOOKUP(B19,[4]EMR!$B$7:$D$131,3,FALSE) -> #N/A | E19: 0
B20: SS Handrail | C20: 46336 | D20: 46376 | E20: 0
B21: OT Rooms
B25: Above Terrace
B26: OHT&Mummty | C26: 46290 | D26: =VLOOKUP(B26,[4]EMR!$B$7:$D$131,3,FALSE) -> 46310 | E26: 0.35
B27: OHT Waterproofing & Tiling | C27: 46315 | D27: =VLOOKUP(B27,[4]EMR!$B$7:$D$131,3,FALSE) -> 46327 | E27: =6/7 -> 0.85714286
B28: LMR | C28: 46078 | D28: =VLOOKUP(B28,[4]EMR!$B$7:$D$131,3,FALSE) -> 46311 | E28: 0.75
B29: Terrace Waterproofing&HRT Tiles | C29: 46272 | D29: =VLOOKUP(B29,[4]EMR!$B$7:$D$131,3,FALSE) -> 46320 | E29: 0.65
B30: Pedestals | C30: 46295 | D30: =VLOOKUP(B30,[4]EMR!$B$7:$D$131,3,FALSE) -> 46325 | E30: 0
B31: Polycarbonate Sheet | C31: 46300 | D31: =VLOOKUP(B31,[4]EMR!$B$7:$D$131,3,FALSE) -> 46320 | E31: 0
B32: External
B33: Shaft brickwork | C33: 46239 | D33: 46315 | E33: 0.35
B34: Plaster | C34: 46183 | D34: 46331 | E34: 0.92
B35: External Stone Cladding | C35: 46310 | D35: =C35+35 -> 46345 | E35: 0
B36: Structural Glazing | C36: 46323 | D36: 46366 | E36: 0
B37: Elevation A | C37: =#REF!+5 -> #REF! | D37: 46315 | E37: 0
B38: Elevation B | C38: =#REF!+5 -> #REF! | D38: 46331 | E38: 0
B39: Elevation C | C39: =#REF!+5 -> #REF! | D39: 46348 | E39: 0
B40: Elevation D | C40: =#REF!+5 -> #REF! | D40: 46361 | E40: 0
B41: MEP
B42: Frist Fix
B43: Electrical | C43: 45940 | D43: 46305 | E43: 0.86
...

Sheet UG Male
B1: UG MALE
E2: Period Highlight: | G2: 46266 | J2: Plan Duration | M2: % Complete
B3: ACTIVITY | C3: PLAN START | D3: Target Date | E3: PERCENT COMPLETE | F3: Remarks | G3: PERIODS
G4: 45901 | H4: =EDATE(G4,1) -> 45931 | I4: =EDATE(H4,1) -> 45962 | J4: =EDATE(I4,1) -> 45992 | K4: =EDATE(J4,1) -> 46023 | L4: =EDATE(K4,1) -> 46054 | M4: =EDATE(L4,1) -> 46082 | N4: =EDATE(M4,1) -> 46113 | O4: =EDATE(N4,1) -> 46143 | ... V4: =EDATE(U4,1) -> 46357
B5: Structure | E5: 1
B6: Finishes
B7: Brickwork | C7: 46193 | D7: 46285 | E7: ='UG MALE backup'!E4/'UG MALE backup'!D4 -> 0.98745819
B8: Plaster | C8: 46222 | D8: 46315 | E8: =('UG MALE backup'!E5+'UG MALE backup'!E7)/('UG MALE backup'!D5+'UG MALE backup'!D7) -> 0.35488004
B9: Aluminum Joineries | C9: 46277 | D9: 46305 | E9: ='UG MALE backup'!E24/'UG MALE backup'!D24 -> 0
B10: Fire door frame & shutter | C10: 46296 | D10: 46305 | E10: ='UG MALE backup'!E27/'UG MALE backup'!D27 -> 0.46153846
B11: Flooring & Dado | C11: 46242 | D11: 46310 | E11: 0.75
B12: False Ceiling | C12: 46285 | D12: 46315 | E12: 0
B13: a) Ground Floor | C13: 46211 | D13: =VLOOKUP(B13,[2]OPD!$B$1:$D$111,3,FALSE) -> 46310 | E13: 0.2
B14: b) First Floor | C14: =C13+25 -> 46236 | D14: =VLOOKUP(B14,[2]OPD!$B$1:$D$111,3,FALSE) -> 46323 | E14: 0
B15: c) Second Floor | C15: =C14+25 -> 46261 | D15: =VLOOKUP(B15,[2]OPD!$B$1:$D$111,3,FALSE) -> 46346 | E15: 0
B16: d) Third Floor | C16: =C15+25 -> 46286 | D16: =VLOOKUP(B16,[2]OPD!$B$1:$D$111,3,FALSE) -> 46371 | E16: 0
B17: SS Handrail | C17: 46285 | D17: 46320 | E17: 0.05
B18: Above Terrace
B19: OHT Waterproofing & Tiling | C19: 46262 | D19: 46301 | E19: ='UG MALE backup'!E48/'UG MALE backup'!D48 -> 0
B20: External (Shaft brickwork & Plaster) | C20: =MIN(C21:C24) -> 46101 | D20: =MAX(D21:D24) -> 46325 | E20: =AVERAGE(E21:E24) -> 0.5925
B21: Elevation A | C21: 46101 | D21: 46264 | E21: 1
B22: Elevation B | C22: 46183 | D22: 46305 | E22: 0.92
B23: Elevation C | C23: 46167 | D23: =VLOOKUP(B23,[2]OPD!$B$1:$D$111,3,FALSE) -> 46295 | E23: 0.45
B24: Elevation D | C24: 46193 | D24: =VLOOKUP(B24,[2]OPD!$B$1:$D$111,3,FALSE) -> 46325 | E24: 0
B25: Elevation A | C25: 46301 | D25: =VLOOKUP(B25,[2]OPD!$B$1:$D$111,3,FALSE) -> 46310 | E25: 0
B26: Elevation B | C26: 46285 | D26: =VLOOKUP(B26,[2]OPD!$B$1:$D$111,3,FALSE) -> 46305 | E26: 0
B27: Elevation C | C27: 46311 | D27: 46325 | E27: 0
B28: Elevation D | C28: 46327 | D28: 46341 | E28: 0
B29: Elevation A | C29: =C25+5 -> 46306 | D29: 46315 | E29: 0
B30: Elevation B | C30: =C26+5 -> 46290 | D30: 46331 | E30: 0
B31: Elevation C | C31: =C27+5 -> 46316 | D31: 46348 | E31: 0
B32: Elevation D | C32: =C28+5 -> 46332 | D32: 46361 | E32: 0
B33: MEP
B34: Frist Fix
B35: Electrical
B36: Cable Tray Installation
B37: PHE
B38: CI Pipiing
B39: GI Piping
B40: HVAC
...

Sheet UG MALE backup
A1: UG Male Building Balance work Updated 17-09-2026
A2: SL no | B2: Activities | C2: UOM | D2: Scope | E2: Completed | F2: Balance | G2: Strike Date | H2: MEP Clearance | I2: Start Date | J2: Target completion date | K2: Remarks
A4: 1 | B4: Brick work | C4: CUM | D4: 1196 | E4: 1181 | F4: 8 | I4: in progress | J4: 46285
A5: 3 | B5: Sand Plastering Internal | C5: Sqm | D5: 5234 | E5: 4924 | F5: =D5-E5 -> 310 | I5: in progress | J5: 20-10-26 | K5: Only drinking area plaster
A6: 4 | B6: Sand Plastering External | C6: Sqm | D6: 6051 | E6: 5301 | F6: =D6-E6 -> 750 | I6: in progress | J6: 46287 | K6: In progress at MFH area and 2 shaft at D elevation
A7: 5 | B7: Gypsum Plaster | C7: Sqm | D7: 11938 | E7: 1170 | F7: =D7-E7 -> 10768 | I7: in progress | J7: 30-09-26 | K7: Repair work at skirting and dor jamb
A8: 6 | B8: Granite sill Jamb DW1 | C8: SQM | D8: 368 | E8: 348 | F8: =D8-E8 -> 20 | I8: in progress | J8: 20-10-26
A9: 6A | B9: Granite sill | C9: Nos | D9: 260 | E9: 220 | F9: =D9-E9 -> 40 | I9: in progress | J9: 15-10-26 | K9: only fire door & shaft
A10: 6B | B10: Granite sill window | C10: Nos | D10: 42 | E10: 35 | F10: =D10-E10 -> 7 | I10: in progress | J10: 20-10-26
A11: 7 | B11: Granite Dado | C11: Sqm | D11: 105 | E11: 0 | F11: =D11-E11 -> 105 | K11: Front available, Waiting for material
A12: 8 | B12: Granite Flooring | C12: Sqm | D12: 125 | E12: 0 | F12: =D12-E12 -> 125 | K12: Completed
A13: 8B | B13: Granite counter | C13: Sqm | D13: 35 | E13: 4 | F13: =D13-E13 -> 31 | I13: in progress | J13: 15-09-26 | K13: work in progress
A14: 2 | B14: Sub Frame - Door | C14: Nos | D14: 137 | E14: 137 | F14: =D14-E14 -> 0 | K14: Completed
A15: 9 | B15: Door Frame Room | C15: Nos | D15: 137 | E15: 137 | F15: =D15-E15 -> 0 | K15: Completed
A16: 10 | B16: Flooring Tile | C16: Sqm | D16: 4646 | E16: 3830 | F16: =D16-E16 -> 816 | I16: in progress | J16: 46305
A17: 10A | B17: Tile grouting | C17: Sqm | D17: 4646 | E17: 0 | F17: =D17-E17 -> 4646 | I17: in progress | J17: 46310
A18: 11 | B18: Skirting Tile | C18: RMT | D18: 2448 | E18: 1713 | F18: =D18-E18 -> 735 | I18: in progress | J18: 46305
A19: 12 | B19: Dado Toilet & Staircase | C19: Sqm | D19: 1350 | E19: 650 | F19: =D19-E19 -> 700 | I19: in progress | J19: 46305 | K19: Team Required & IWC fixing pending all toilet, Juan Dark 450*300 & yana dark 300* 450 tile not available in store
A20: 13 | B20: Kota stone flooring | C20: Sqm | D20: 110 | E20: 83 | F20: =D20-E20 -> 27 | I20: in progress | J20: 46295
A21: 14 | B21: Internal Painting | C21: Sqm | D21: 17172 | E21: 0 | F21: =D21-E21 -> 17172 | I21: in progress | J21: 46300 | K21: 1st coat putty in progress at 3rd floor
A22: 15 | B22: External Painting | C22: Sqm | D22: 5457 | E22: 0 | F22: =D22-E22 -> 5457 | I22: 46296 | J22: 20-11-26 | K22: Team required
A23: 16 | B23: False ceiling | C23: Sqm | D23: 535 | E23: 0 | F23: =D23-E23 -> 535 | H23: MEP Clearence require | I23: 20-09-26 | J23: 20-10-26 | K23: As per site required height is not available
A24: 17 | B24: Alu. Flush Door | C24: Nos | D24: 137 | E24: 0 | F24: =D24-E24 -> 137 | I24: 46277 | J24: 46305 | K24: Material available
A25: 18 | B25: WPC Door | C25: Nos | D25: 86 | E25: 0 | F25: =D25-E25 -> 86 | I25: in progress | J25: 30-09-26 | K25: work in progress
A26: 19 | B26: Bison Door | C26: Nos | D26: 10 | E26: 0 | F26: =D26-E26 -> 10 | H26: front available | K26: Approval & materal, team required
A27: 20 | B27: Fire Door | C27: Nos | D27: 26 | E27: 12 | F27: =D27-E27 -> 14 | H27: Front available | I27: 46296 | J27: 46305 | K27: fire rated tennical issue by client
A28: 21 | B28: Alu. DW1 | C28: Nos | D28: 121 | E28: 0 | F28: =D28-E28 -> 121 | H28: Front available | I28: 15-09-26 | J28: 30-09-26 | K28: material not available
A29: 22 | B29: Alu.Windaw frame | C29: Nos | D29: 42 | E29: 14 | F29: =D29-E29 -> 28 | H29: Front available | I29: 15-09-26 | J29: 30-09-26 | K29: material not available
A30: 17B | B30: Alu. Flush Door DW1 | C30: Nos | D30: 121 | E30: 0 | F30: =D30-E30 -> 121 | H30: front available | I30: 15-09-26 | J30: 30-09-26 | K30: material not available
B31: GRC MS frame | C31: Nos | D31: 104 | E31: 88 | F31: =D31-E31 -> 16 | J31: 16-09-26
A32: 23 | B32: GR01 jali | C32: Nos | D32: 104 | E32: 78 | F32: =D32-E32 -> 26 | J32: 46290 | K32: After Completion f External Plaster
A33: 24 | B33: Balcony Handrail | C33: Nos | D33: 121 | E33: 0 | F33: =D33-E33 -> 121 | K33: Need aproved GFC drawing
A34: 25 | B34: Brick work below railing & Outer Plaster | C34: RMT | D34: =121*4 -> 484 | E34: 0 | F34: 484 | K34: After Fixing of railing
A35: 26 | B35: waterproofing balcony | C35: Sqm | D35: 242 | E35: 0 | F35: 242 | K35: After Fixing of railing
A36: 27 | B36: Balcony Tiling | C36: Sqm | D36: 310 | E36: 0 | F36: 280 | K36: After Fixing of railing
A37: 28 | B37: Granite top | C37: Sqm | D37: 96 | E37: 0 | F37: 96 | K37: After Fixing of railing
A38: Terrace UG Male Building Balance work
A39: SL no | B39: Activities | C39: UOM | D39: Scope | E39: Completed | F39: Balance | G39: Strike Date | H39: MEP Clearance | I39: Start Date | J39: Target completion date | K39: Remarks
A41: 1 | B41: Brick work | C41: CUM | D41: 63 | E41: 63 | F41: =D41-E41 -> 0
A42: 2 | B42: Sand Plastering Internal | C42: Sqm | D42: 180 | E42: 180 | F42: =D42-E42 -> 0 | G42: =F42/31 -> 0
...

Sheet OPD  
B1: OPD BUILDING
E2: Period Highlight: | G2: 46296 | J2: Plan Duration | M2: % Complete
B3: ACTIVITY | C3: PLAN START | D3: Target Date | E3: PERCENT COMPLETE | F3: Remarks | G3: PERIODS
G4: 45901 | H4: =EDATE(G4,1) -> 45931 | I4: =EDATE(H4,1) -> 45962 | J4: =EDATE(I4,1) -> 45992 | K4: =EDATE(J4,1) -> 46023 | L4: =EDATE(K4,1) -> 46054 | M4: =EDATE(L4,1) -> 46082 | N4: =EDATE(M4,1) -> 46113 | O4: =EDATE(N4,1) -> 46143 | ... V4: =EDATE(U4,1) -> 46357
B5: Structure | E5: 1
B6: Finishes
B7: Brickwork | C7: 45910 | D7: 46305 | E7: 0.95
B8: Plaster | C8: 45991 | D8: =VLOOKUP(B$8,[2]OPD!$B$1:$D$111,3,FALSE) -> 46320 | E8: =('UG MALE backup'!E5+'UG MALE backup'!E7)/('UG MALE backup'!D5+'UG MALE backup'!D7) -> 0.35488004
B9: Joineries | C9: 46047 | D9: 46341 | E9: 0.55
B10: Fire door frame & shutter | C10: 46102 | D10: =VLOOKUP(B10,[2]OPD!$B$1:$D$111,3,FALSE) -> 46325 | E10: 0.45
B11: Flooring & Dado | D11: =VLOOKUP(B11,[2]OPD!$B$1:$D$111,3,FALSE) -> 46346 | E11: 0.75
B12: False Ceiling | C12: =MIN(C13:C16) -> 46211 | D12: =MAX(D13:D16) -> 46371 | E12: =AVERAGE(E13:E16) -> 0.05
B13: a) Ground Floor | C13: 46211 | D13: =VLOOKUP(B13,[2]OPD!$B$1:$D$111,3,FALSE) -> 46310 | E13: 0.2
B14: b) First Floor | C14: =C13+25 -> 46236 | D14: =VLOOKUP(B14,[2]OPD!$B$1:$D$111,3,FALSE) -> 46323 | E14: 0
B15: c) Second Floor | C15: =C14+25 -> 46261 | D15: =VLOOKUP(B15,[2]OPD!$B$1:$D$111,3,FALSE) -> 46346 | E15: 0
B16: d) Third Floor | C16: =C15+25 -> 46286 | D16: =VLOOKUP(B16,[2]OPD!$B$1:$D$111,3,FALSE) -> 46371 | E16: 0
B17: Lift facia granite | C17: 46252 | D17: =VLOOKUP(B17,[2]OPD!$B$1:$D$111,3,FALSE) -> 46351 | E17: 0
B18: SS Handrail | C18: 46310 | D18: =VLOOKUP(B18,[2]OPD!$B$1:$D$111,3,FALSE) -> 46355 | E18: 0
B19: Courtyard Plaster inc. Ramp | C19: 46228 | D19: =VLOOKUP(B19,[2]OPD!$B$1:$D$111,3,FALSE) -> 46325 | E19: 0.33
B20: Ramp Flooring | C20: 46290 | D20: =VLOOKUP(B20,[2]OPD!$B$1:$D$111,3,FALSE) -> 46351 | E20: 0
B21: Above Terrace
B22: OHT Waterproofing & Tiling | C22: 46225 | D22: 46351 | E22: 0.35
B23: LMR | C23: 46128 | D23: =VLOOKUP(B23,[2]OPD!$B$1:$D$111,3,FALSE) -> 46295 | E23: =6/7 -> 0.85714286
B24: Terrace Waterproofing&HRT Tiles | C24: 46239 | D24: 46361 | E24: 0.75
B25: Pedestals | C25: 46062 | D25: =VLOOKUP(B25,[2]OPD!$B$1:$D$111,3,FALSE) -> 46300 | E25: 0.65
B26: Polycarbonate Sheet | C26: 46295 | D26: =VLOOKUP(B26,[2]OPD!$B$1:$D$111,3,FALSE) -> 46315 | E26: 0
B27: External (Shaft brickwork & Plaster) | C27: =MIN(C28:C31) -> 46101 | D27: =MAX(D28:D31) -> 46325 | E27: =AVERAGE(E28:E31) -> 0.5925
B28: Elevation A | C28: 46101 | D28: 46264 | E28: 1
B29: Elevation B | C29: 46183 | D29: 46305 | E29: 0.92
B30: Elevation C | C30: 46167 | D30: =VLOOKUP(B30,[2]OPD!$B$1:$D$111,3,FALSE) -> 46295 | E30: 0.45
B31: Elevation D | C31: 46193 | D31: =VLOOKUP(B31,[2]OPD!$B$1:$D$111,3,FALSE) -> 46325 | E31: 0
B32: External Stone Cladding | C32: =MIN(C33:C36) -> 46285 | D32: =MAX(D33:D36) -> 46341 | E32: =AVERAGE(E33:E36) -> 0
B33: Elevation A | C33: 46301 | D33: =VLOOKUP(B33,[2]OPD!$B$1:$D$111,3,FALSE) -> 46310 | E33: 0
B34: Elevation B | C34: 46285 | D34: =VLOOKUP(B34,[2]OPD!$B$1:$D$111,3,FALSE) -> 46305 | E34: 0
B35: Elevation C | C35: 46311 | D35: 46325 | E35: 0
B36: Elevation D | C36: 46327 | D36: 46341 | E36: 0
B37: Structural Glazing | C37: =MIN(C38:C41) -> 46290 | D37: =MAX(D38:D41) -> 46361 | E37: =AVERAGE(E38:E41) -> 0
B38: Elevation A | C38: =C33+5 -> 46306 | D38: 46315 | E38: 0
B39: Elevation B | C39: =C34+5 -> 46290 | D39: 46331 | E39: 0
B40: Elevation C | C40: =C35+5 -> 46316 | D40: 46348 | E40: 0
...
